<?xml version="1.0"?>
<robot xmlns:xacro="http://www.ros.org/wiki/xacro" name="diff_robot">

  <!-- 参数定义 -->
  <xacro:property name="chassis_length" value="0.4"/>
  <xacro:property name="chassis_width" value="0.3"/>
  <xacro:property name="chassis_height" value="0.1"/>
  <xacro:property name="chassis_mass" value="5.0"/>
  
  <xacro:property name="wheel_radius" value="0.05"/>
  <xacro:property name="wheel_width" value="0.02"/>
  <xacro:property name="wheel_mass" value="0.5"/>
  <xacro:property name="wheel_separation" value="0.35"/>
  
  <!-- 惯性宏 -->
  <xacro:macro name="box_inertia" params="m x y z">
    <inertial>
      <mass value="${m}"/>
      <inertia ixx="${m*(y*y+z*z)/12}" ixy="0" ixz="0"
               iyy="${m*(x*x+z*z)/12}" iyz="0"
               izz="${m*(x*x+y*y)/12}"/>
    </inertial>
  </xacro:macro>

  <xacro:macro name="cylinder_inertia" params="m r h">
    <inertial>
      <mass value="${m}"/>
      <inertia ixx="${m*(3*r*r+h*h)/12}" ixy="0" ixz="0"
               iyy="${m*(3*r*r+h*h)/12}" iyz="0"
               izz="${m*r*r/2}"/>
    </inertial>
  </xacro:macro>

  <!-- 底盘 -->
  <link name="base_link">
    <visual>
      <geometry>
        <box size="${chassis_length} ${chassis_width} ${chassis_height}"/>
      </geometry>
      <material name="blue">
        <color rgba="0.2 0.2 0.8 1.0"/>
      </material>
    </visual>
    <collision>
      <geometry>
        <box size="${chassis_length} ${chassis_width} ${chassis_height}"/>
      </geometry>
    </collision>
    <xacro:box_inertia m="${chassis_mass}" x="${chassis_length}" y="${chassis_width}" z="${chassis_height}"/>
  </link>

  <!-- 轮子宏 -->
  <xacro:macro name="wheel" params="prefix y_offset">
    <link name="${prefix}_wheel">
      <visual>
        <origin xyz="0 0 0" rpy="${pi/2} 0 0"/>
        <geometry>
          <cylinder radius="${wheel_radius}" length="${wheel_width}"/>
        </geometry>
        <material name="black">
          <color rgba="0.1 0.1 0.1 1.0"/>
        </material>
      </visual>
      <collision>
        <origin xyz="0 0 0" rpy="${pi/2} 0 0"/>
        <geometry>
          <cylinder radius="${wheel_radius}" length="${wheel_width}"/>
        </geometry>
      </collision>
      <xacro:cylinder_inertia m="${wheel_mass}" r="${wheel_radius}" h="${wheel_width}"/>
    </link>

    <joint name="${prefix}_wheel_joint" type="continuous">
      <parent link="base_link"/>
      <child link="${prefix}_wheel"/>
      <origin xyz="0 ${y_offset} ${-chassis_height/2}" rpy="0 0 0"/>
      <axis xyz="0 1 0"/>
      <dynamics damping="0.1" friction="0.1"/>
    </joint>
  </xacro:macro>

  <!-- 左右轮 -->
  <xacro:wheel prefix="left" y_offset="${wheel_separation/2}"/>
  <xacro:wheel prefix="right" y_offset="${-wheel_separation/2}"/>

  <!-- ros2_control 硬件接口 -->
  <ros2_control name="GazeboSystem" type="system">
    <hardware>
      <plugin>gazebo_ros2_control/GazeboSystem</plugin>
    </hardware>
    <joint name="left_wheel_joint">
      <command_interface name="velocity">
        <min>-1.0</min>
        <max>1.0</max>
      </command_interface>
      <state_interface name="position"/>
      <state_interface name="velocity"/>
    </joint>
    <joint name="right_wheel_joint">
      <command_interface name="velocity">
        <min>-1.0</min>
        <max>1.0</max>
      </command_interface>
      <state_interface name="position"/>
      <state_interface name="velocity"/>
    </joint>
  </ros2_control>

  <!-- Gazebo ros2_control 插件 -->
  <gazebo>
    <plugin name="gazebo_ros2_control" filename="libgazebo_ros2_control.so">
      <parameters>$(find diff_robot_control)/config/diff_robot_controllers.yaml</parameters>
    </plugin>
  </gazebo>

  <!-- 万向轮 -->
  <link name="caster_wheel">
    <visual>
      <geometry>
        <sphere radius="0.02"/>
      </geometry>
      <material name="gray">
        <color rgba="0.5 0.5 0.5 1.0"/>
      </material>
    </visual>
    <collision>
      <geometry>
        <sphere radius="0.02"/>
      </geometry>
    </collision>
    <inertial>
      <mass value="0.1"/>
      <inertia ixx="0.0001" ixy="0" ixz="0" iyy="0.0001" iyz="0" izz="0.0001"/>
    </inertial>
  </link>

  <joint name="caster_joint" type="continuous">
    <parent link="base_link"/>
    <child link="caster_wheel"/>
    <origin xyz="${-chassis_length/2 + 0.05} 0 ${-chassis_height/2}" rpy="0 0 0"/>
    <axis xyz="1 0 0"/>
    <dynamics damping="0.5" friction="0.1"/>
  </joint>

</robot>